Workbook
Name Slicer_Crime_Category: #N/A
Name Slicer_Crime_Head: #N/A
Name Slicer_State_UT: #N/A

Sheet NCRB_CII_2023_Table_3A.2_0
A1: State/UT | B1: Murder with Rape/Gang Rape | C1: Dowry Deaths | D1: Abetment to Suicide of Women | E1: Miscarriage | F1: Acid Attack | G1: Attempt to Acid Attack | H1: Cruelty by Husband/Relatives | I1: Kidnapping & Abduction (Total) | J1: Kidnapping & Abduction | K1: Kidnapping for Murder | L1: Kidnapping for Ransom | M1: Kidnapping for Marriage (Total) | N1: Kidnapping for Marriage - Women 18+ | O1: Kidnapping for Marriage - Girls <18 | P1: Kidnapping for Procuration - Girls < 18 | Q1: Kidnapping for Importation - Girls < 18 | R1: Other Kidnapping Cases | S1: Human Trafficking | T1: Selling of Girls < 18 | U1: Buying of Girls < 18 | V1: Rape (Total) | W1: Rape - Women 18+ | X1: Rape - Girls <18 | Y1: Attempt to Rape (Total) | Z1: Attempt to Rape - Women 18+ | AA1: Attempt to Rape - Girls <18 | AB1: Assault to Outrage Modesty (Total) | AC1: Assault to Outrage Modesty - Women 18+ | AD1: Assault to Outrage Modesty - Girls < 18 | AE1: Insult to Modesty (Total) | AF1: Insult to Modesty - Women 18+ | AG1: Insult to Modesty - Girls <18 | AH1: Dowry Prohibition Act | AI1: Immoral Traffic (Prevention) Act (Total) | AJ1: Immoral Traffic (Prevention) Act - Procuring Children | AK1: Immoral Traffic (Prevention) Act - Detaining Person | AL1: Immoral Traffic (Prevention) Act - Public Prostitution | AM1: Immoral Traffic (Prevention) Act - Soliciting | AN1: Immoral Traffic (Prevention) Act - Other | AO1: Domestic Violence Act | AP1: Women-Centric Cyber Crime (Total) | AQ1: Publishing Explicit Material | AR1: Other Women-Centric Cyber Crime | AS1: POCSO (Protection of Children from Sexual Offences Act) (Total) | AT1: POCSO - Child Rape | AU1: POCSO - Sexual Assault | AV1: POCSO - Sexual Harassment | AW1: POCSO - Child Pornography | AX1: POCSO - Other Offences | AY1: POCSO - Unnatural Offences | AZ1: Indecent Representation of Women Act
A2: Andhra Pradesh | B2: 5 | C2: 95 | D2: 386 | E2: 10 | F2: 3 | G2: 4 | H2: 10594 | I2: 524 | J2: 334 | K2: 1 | L2: 5 | M2: 132 | N2: 58 | O2: 74 | P2: 26 | Q2: 0 | R2: 26 | S2: 79 | T2: 0 | U2: 2 | V2: 438 | W2: 438 | X2: 0 | Y2: 112 | Z2: 96 | AA2: 16 | AB2: 4930 | AC2: 4930 | AD2: 0 | AE2: 2826 | AF2: 2826 | AG2: 0 | AH2: 353 | AI2: 68 | AJ2: 11 | AK2: 1 | AL2: 11 | AM2: 0 | AN2: 45 | AO2: 0 | AP2: 79 | AQ2: 68 | AR2: 11 | AS2: 1907 | AT2: 855 | AU2: 552 | AV2: 488 | AW2: 9 | AX2: 3 | AY2: 0 | AZ2: 3
A3: Arunachal Pradesh | B3: 0 | C3: 1 | D3: 3 | E3: 0 | F3: 0 | G3: 0 | H3: 58 | I3: 38 | J3: 28 | K3: 0 | L3: 1 | M3: 3 | N3: 2 | O3: 1 | P3: 1 | Q3: 0 | R3: 5 | S3: 5 | T3: 0 | U3: 0 | V3: 71 | W3: 35 | X3: 36 | Y3: 5 | Z3: 3 | AA3: 2 | AB3: 74 | AC3: 69 | AD3: 5 | AE3: 16 | AF3: 16 | AG3: 0 | AH3: 0 | AI3: 0 | AJ3: 0 | AK3: 0 | AL3: 0 | AM3: 0 | AN3: 0 | AO3: 0 | AP3: 0 | AQ3: 0 | AR3: 0 | AS3: 55 | AT3: 42 | AU3: 11 | AV3: 1 | AW3: 1 | AX3: 0 | AY3: 0 | AZ3: 0
A4: Assam | B4: 13 | C4: 101 | D4: 102 | E4: 4 | F4: 4 | G4: 2 | H4: 2923 | I4: 3110 | J4: 645 | K4: 3 | L4: 15 | M4: 1371 | N4: 1000 | O4: 371 | P4: 454 | Q4: 0 | R4: 622 | S4: 81 | T4: 5 | U4: 0 | V4: 989 | W4: 988 | X4: 1 | Y4: 173 | Z4: 173 | AA4: 0 | AB4: 1595 | AC4: 1582 | AD4: 13 | AE4: 42 | AF4: 42 | AG4: 0 | AH4: 162 | AI4: 30 | AJ4: 3 | AK4: 0 | AL4: 0 | AM4: 0 | AN4: 27 | AO4: 3 | AP4: 182 | AQ4: 97 | AR4: 85 | AS4: 2549 | AT4: 1816 | AU4: 475 | AV4: 121 | AW4: 12 | AX4: 125 | AY4: 0 | AZ4: 0
A5: Bihar | B5: 4 | C5: 1143 | D5: 3 | E5: 0 | F5: 5 | G5: 0 | H5: 2032 | I5: 12136 | J5: 868 | K5: 6 | L5: 2 | M5: 9467 | N5: 4534 | O5: 4933 | P5: 0 | Q5: 0 | R5: 1793 | S5: 28 | T5: 0 | U5: 0 | V5: 902 | W5: 902 | X5: 0 | Y5: 47 | Z5: 30 | AA5: 17 | AB5: 472 | AC5: 465 | AD5: 7 | AE5: 47 | AF5: 47 | AG5: 0 | AH5: 3665 | AI5: 58 | AJ5: 29 | AK5: 11 | AL5: 2 | AM5: 0 | AN5: 16 | AO5: 1 | AP5: 100 | AQ5: 20 | AR5: 80 | AS5: 2307 | AT5: 925 | AU5: 844 | AV5: 190 | AW5: 345 | AX5: 0 | AY5: 3 | AZ5: 2
A6: Chhattisgarh | B6: 5 | C6: 46 | D6: 122 | E6: 5 | F6: 1 | G6: 0 | H6: 755 | I6: 2440 | J6: 2345 | K6: 0 | L6: 0 | M6: 77 | N6: 1 | O6: 76 | P6: 1 | Q6: 0 | R6: 17 | S6: 14 | T6: 0 | U6: 0 | V6: 1171 | W6: 1171 | X6: 0 | Y6: 5 | Z6: 1 | AA6: 4 | AB6: 1034 | AC6: 1032 | AD6: 2 | AE6: 241 | AF6: 239 | AG6: 2 | AH6: 8 | AI6: 12 | AJ6: 0 | AK6: 0 | AL6: 11 | AM6: 0 | AN6: 1 | AO6: 0 | AP6: 198 | AQ6: 195 | AR6: 3 | AS6: 1978 | AT6: 1503 | AU6: 441 | AV6: 25 | AW6: 6 | AX6: 2 | AY6: 1 | AZ6: 0
A7: Goa | B7: 0 | C7: 1 | D7: 3 | E7: 0 | F7: 0 | G7: 0 | H7: 0 | I7: 51 | J7: 41 | K7: 0 | L7: 0 | M7: 0 | N7: 0 | O7: 0 | P7: 0 | Q7: 0 | R7: 10 | S7: 8 | T7: 0 | U7: 0 | V7: 97 | W7: 35 | X7: 62 | Y7: 0 | Z7: 0 | AA7: 0 | AB7: 96 | AC7: 75 | AD7: 21 | AE7: 21 | AF7: 20 | AG7: 1 | AH7: 0 | AI7: 0 | AJ7: 0 | AK7: 0 | AL7: 0 | AM7: 0 | AN7: 0 | AO7: 0 | AP7: 9 | AQ7: 8 | AR7: 1 | AS7: 0 | AT7: 0 | AU7: 0 | AV7: 0 | AW7: 0 | AX7: 0 | AY7: 0 | AZ7: 0
A8: Gujarat | B8: 7 | C8: 12 | D8: 318 | E8: 5 | F8: 2 | G8: 1 | H8: 2176 | I8: 1257 | J8: 646 | K8: 0 | L8: 1 | M8: 567 | N8: 43 | O8: 524 | P8: 1 | Q8: 0 | R8: 42 | S8: 3 | T8: 0 | U8: 0 | V8: 634 | W8: 632 | X8: 2 | Y8: 0 | Z8: 0 | AA8: 0 | AB8: 688 | AC8: 622 | AD8: 66 | AE8: 15 | AF8: 15 | AG8: 0 | AH8: 3 | AI8: 80 | AJ8: 6 | AK8: 22 | AL8: 42 | AM8: 1 | AN8: 9 | AO8: 2 | AP8: 54 | AQ8: 45 | AR8: 9 | AS8: 2548 | AT8: 2279 | AU8: 232 | AV8: 25 | AW8: 6 | AX8: 5 | AY8: 1 | AZ8: 0
A9: Haryana | B9: 9 | C9: 207 | D9: 178 | E9: 50 | F9: 3 | G9: 1 | H9: 5191 | I9: 3204 | J9: 366 | K9: 3 | L9: 0 | M9: 968 | N9: 656 | O9: 312 | P9: 788 | Q9: 0 | R9: 1079 | S9: 32 | T9: 0 | U9: 0 | V9: 1772 | W9: 1769 | X9: 3 | Y9: 199 | Z9: 199 | AA9: 0 | AB9: 2265 | AC9: 2239 | AD9: 26 | AE9: 443 | AF9: 442 | AG9: 1 | AH9: 14 | AI9: 38 | AJ9: 11 | AK9: 2 | AL9: 9 | AM9: 0 | AN9: 16 | AO9: 5 | AP9: 103 | AQ9: 96 | AR9: 7 | AS9: 2044 | AT9: 1372 | AU9: 521 | AV9: 124 | AW9: 4 | AX9: 23 | AY9: 0 | AZ9: 0
A10: Himachal Pradesh | B10: 6 | C10: 0 | D10: 39 | E10: 0 | F10: 0 | G10: 0 | H10: 217 | I10: 351 | J10: 200 | K10: 0 | L10: 0 | M10: 144 | N10: 13 | O10: 131 | P10: 3 | Q10: 0 | R10: 4 | S10: 5 | T10: 0 | U10: 0 | V10: 344 | W10: 138 | X10: 206 | Y10: 3 | Z10: 3 | AA10: 0 | AB10: 504 | AC10: 448 | AD10: 56 | AE10: 97 | AF10: 97 | AG10: 0 | AH10: 2 | AI10: 10 | AJ10: 6 | AK10: 0 | AL10: 0 | AM10: 0 | AN10: 4 | AO10: 2 | AP10: 21 | AQ10: 21 | AR10: 0 | AS10: 3 | AT10: 0 | AU10: 0 | AV10: 2 | AW10: 1 | AX10: 0 | AY10: 0 | AZ10: 0
A11: Jharkhand | B11: 3 | C11: 218 | D11: 45 | E11: 3 | F11: 1 | G11: 0 | H11: 770 | I11: 1253 | J11: 93 | K11: 4 | L11: 5 | M11: 775 | N11: 620 | O11: 155 | P11: 319 | Q11: 0 | R11: 57 | S11: 37 | T11: 0 | U11: 0 | V11: 1221 | W11: 1071 | X11: 150 | Y11: 66 | Z11: 64 | AA11: 2 | AB11: 944 | AC11: 942 | AD11: 2 | AE11: 4 | AF11: 4 | AG11: 0 | AH11: 1487 | AI11: 2 | AJ11: 0 | AK11: 1 | AL11: 0 | AM11: 0 | AN11: 1 | AO11: 96 | AP11: 12 | AQ11: 12 | AR11: 0 | AS11: 827 | AT11: 657 | AU11: 93 | AV11: 69 | AW11: 7 | AX11: 1 | AY11: 0 | AZ11: 0
A12: Karnataka | B12: 6 | C12: 156 | D12: 274 | E12: 11 | F12: 0 | G12: 4 | H12: 3000 | I12: 2327 | J12: 2256 | K12: 1 | L12: 18 | M12: 29 | N12: 21 | O12: 8 | P12: 5 | Q12: 0 | R12: 18 | S12: 11 | T12: 0 | U12: 0 | V12: 656 | W12: 656 | X12: 0 | Y12: 10 | Z12: 9 | AA12: 1 | AB12: 6790 | AC12: 6789 | AD12: 1 | AE12: 148 | AF12: 148 | AG12: 0 | AH12: 2322 | AI12: 308 | AJ12: 106 | AK12: 94 | AL12: 37 | AM12: 3 | AN12: 68 | AO12: 0 | AP12: 458 | AQ12: 457 | AR12: 1 | AS12: 3854 | AT12: 3099 | AU12: 506 | AV12: 196 | AW12: 30 | AX12: 22 | AY12: 1 | AZ12: 1
A13: Kerala | B13: 4 | C13: 8 | D13: 47 | E13: 1 | F13: 5 | G13: 4 | H13: 4710 | I13: 191 | J13: 104 | K13: 1 | L13: 0 | M13: 39 | N13: 15 | O13: 24 | P13: 2 | Q13: 0 | R13: 45 | S13: 15 | T13: 0 | U13: 0 | V13: 843 | W13: 843 | X13: 0 | Y13: 54 | Z13: 54 | AA13: 0 | AB13: 4816 | AC13: 4586 | AD13: 230 | AE13: 679 | AF13: 671 | AG13: 8 | AH13: 21 | AI13: 13 | AJ13: 0 | AK13: 1 | AL13: 3 | AM13: 1 | AN13: 8 | AO13: 480 | AP13: 369 | AQ13: 333 | AR13: 36 | AS13: 3765 | AT13: 1719 | AU13: 1529 | AV13: 469 | AW13: 34 | AX13: 14 | AY13: 0 | AZ13: 0
... A38: Total All India | B38: 230 | C38: 6156 | D38: 4825 | E38: 309 | F38: 113 | G38: 41 | H38: 133676 | I38: 88605 | J38: 47867 | K38: 53 | L38: 115 | M38: 30496 | N38: 15859 | O38: 14637 | P38: 1858 | Q38: 2 | R38: 8214 | S38: 1211 | T38: 11 | U38: 4 | V38: 29670 | W38: 28821 | X38: 849 | Y38: 2796 | Z38: 2702 | AA38: 94 | AB38: 83891 | AC38: 82544 | AD38: 1347 | AE38: 8823 | AF38: 8804 | AG38: 19 | AH38: 15489 | AI38: 1788 | AJ38: 403 | AK38: 253 | AL38: 213 | AM38: 124 | AN38: 795 | AO38: 632 | AP38: 3678 | AQ38: 2767 | AR38: 911 | AS38: 66232 | AT38: 40046 | AU38: 22149 | AV38: 2778 | AW38: 698 | AX38: 513 | AY38: 48 | AZ38: 31

Sheet Normalized_Data
A1: State/UT | B1: Crime Head | C1: Crime Category | D1: Cases
A2: Andhra Pradesh | B2: Murder with Rape/Gang Rape | C2: Murder with Rape | D2: 5
A3: Andhra Pradesh | B3: Dowry Deaths | C3: Dowry Death | D3: 95
A4: Andhra Pradesh | B4: Abetment to Suicide of Women | C4: Abetment to Suicide | D4: 386
A5: Andhra Pradesh | B5: Miscarriage | C5: Miscarriage | D5: 10
A6: Andhra Pradesh | B6: Acid Attack | C6: Acid Attack | D6: 3
A7: Andhra Pradesh | B7: Attempt to Acid Attack | C7: Acid Attack | D7: 4
A8: Andhra Pradesh | B8: Cruelty by Husband/Relatives | C8: Domestic Violence | D8: 10594
A9: Andhra Pradesh | B9: Kidnapping & Abduction (Total) | C9: Kidnapping & Abduction | D9: 524
A10: Andhra Pradesh | B10: Kidnapping & Abduction | C10: Kidnapping & Abduction | D10: 334
A11: Andhra Pradesh | B11: Kidnapping for Murder | C11: Kidnapping & Abduction | D11: 1
A12: Andhra Pradesh | B12: Kidnapping for Ransom | C12: Kidnapping & Abduction | D12: 5
A13: Andhra Pradesh | B13: Kidnapping for Marriage (Total) | C13: Kidnapping & Abduction | D13: 132
... A1837: Puducherry | B1837: Indecent Representation of Women Act | C1837: Indecent Representation | D1837: 0

Sheet Detailed_Data_Breakdown
A1: Analysis Include | B1: Yes
A3: Crime Head | B3: Reported Cases | C3: Percentage of Total
A4: Cruelty by Husband/Relatives | B4: 133676 | C4: 0.29168749
A5: Kidnapping & Abduction (Total) | B5: 88605 | C5: 0.19334039
A6: Assault to Outrage Modesty (Total) | B6: 83891 | C6: 0.18305421
A7: POCSO (Protection of Children from Sexual Offences Act) (Total) | B7: 66232 | C7: 0.14452142
A8: Rape (Total) | B8: 29670 | C8: 0.064741373
A9: Dowry Prohibition Act | B9: 15489 | C9: 0.033797746
A10: Insult to Modesty (Total) | B10: 8823 | C10: 0.019252212
A11: Other Kidnapping Cases | B11: 8214 | C11: 0.017923345
A12: Dowry Deaths | B12: 6156 | C12: 0.013432689
A13: Abetment to Suicide of Women | B13: 4825 | C13: 0.010528383
A14: Women-Centric Cyber Crime (Total) | B14: 3678 | C14: 0.0080255736
A15: Attempt to Rape (Total) | B15: 2796 | C15: 0.006101007
... A28: Grand Total | B28: 458285 | C28: 1

Sheet Dashboard_Data
A1: State/UT | B1: Crime Head | C1: Crime Category | D1: Cases | E1: Record Level | F1: Analysis Include
A2: Andhra Pradesh | B2: Murder with Rape/Gang Rape | C2: Murder with Rape | D2: 5 | E2: Standalone | F2: =IF(E2="Standalone","Yes",IF(AND(E2="Total",OR(B2="Kidnapping & Abduction (Total)",B2="Rape (Total)",B2="Attempt to Rape (Total)",B2="Assault to Outrage Modesty (Total)",B2="Insult to Modesty (Total)",B2="Immoral Traffic (Prevention) Act (Total)",B2="Women-Centric Cyber Crime (Total)",B2="POCSO (Protection of Children from Sexual Offences Act) (Total)")),"Yes","No")) -> Yes
A3: Andhra Pradesh | B3: Dowry Deaths | C3: Dowry Death | D3: 95 | E3: Standalone | F3: =IF(E3="Standalone","Yes",IF(AND(E3="Total",OR(B3="Kidnapping & Abduction (Total)",B3="Rape (Total)",B3="Attempt to Rape (Total)",B3="Assault to Outrage Modesty (Total)",B3="Insult to Modesty (Total)",B3="Immoral Traffic (Prevention) Act (Total)",B3="Women-Centric Cyber Crime (Total)",B3="POCSO (Protection of Children from Sexual Offences Act) (Total)")),"Yes","No")) -> Yes
A4: Andhra Pradesh | B4: Abetment to Suicide of Women | C4: Abetment to Suicide | D4: 386 | E4: Standalone | F4: =IF(E4="Standalone","Yes",IF(AND(E4="Total",OR(B4="Kidnapping & Abduction (Total)",B4="Rape (Total)",B4="Attempt to Rape (Total)",B4="Assault to Outrage Modesty (Total)",B4="Insult to Modesty (Total)",B4="Immoral Traffic (Prevention) Act (Total)",B4="Women-Centric Cyber Crime (Total)",B4="POCSO (Protection of Children from Sexual Offences Act) (Total)")),"Yes","No")) -> Yes
A5: Andhra Pradesh | B5: Miscarriage | C5: Miscarriage | D5: 10 | E5: Standalone | F5: =IF(E5="Standalone","Yes",IF(AND(E5="Total",OR(B5="Kidnapping & Abduction (Total)",B5="Rape (Total)",B5="Attempt to Rape (Total)",B5="Assault to Outrage Modesty (Total)",B5="Insult to Modesty (Total)",B5="Immoral Traffic (Prevention) Act (Total)",B5="Women-Centric Cyber Crime (Total)",B5="POCSO (Protection of Children from Sexual Offences Act) (Total)")),"Yes","No")) -> Yes
A6: Andhra Pradesh | B6: Acid Attack | C6: Acid Attack | D6: 3 | E6: Standalone | F6: =IF(E6="Standalone","Yes",IF(AND(E6="Total",OR(B6="Kidnapping & Abduction (Total)",B6="Rape (Total)",B6="Attempt to Rape (Total)",B6="Assault to Outrage Modesty (Total)",B6="Insult to Modesty (Total)",B6="Immoral Traffic (Prevention) Act (Total)",B6="Women-Centric Cyber Crime (Total)",B6="POCSO (Protection of Children from Sexual Offences Act) (Total)")),"Yes","No")) -> Yes
A7: Andhra Pradesh | B7: Attempt to Acid Attack | C7: Acid Attack | D7: 4 | E7: Standalone | F7: =IF(E7="Standalone","Yes",IF(AND(E7="Total",OR(B7="Kidnapping & Abduction (Total)",B7="Rape (Total)",B7="Attempt to Rape (Total)",B7="Assault to Outrage Modesty (Total)",B7="Insult to Modesty (Total)",B7="Immoral Traffic (Prevention) Act (Total)",B7="Women-Centric Cyber Crime (Total)",B7="POCSO (Protection of Children from Sexual Offences Act) (Total)")),"Yes","No")) -> Yes
A8: Andhra Pradesh | B8: Cruelty by Husband/Relatives | C8: Domestic Violence | D8: 10594 | E8: Standalone | F8: =IF(E8="Standalone","Yes",IF(AND(E8="Total",OR(B8="Kidnapping & Abduction (Total)",B8="Rape (Total)",B8="Attempt to Rape (Total)",B8="Assault to Outrage Modesty (Total)",B8="Insult to Modesty (Total)",B8="Immoral Traffic (Prevention) Act (Total)",B8="Women-Centric Cyber Crime (Total)",B8="POCSO (Protection of Children from Sexual Offences Act) (Total)")),"Yes","No")) -> Yes
A9: Andhra Pradesh | B9: Kidnapping & Abduction (Total) | C9: Kidnapping & Abduction | D9: 524 | E9: Total | F9: =IF(E9="Standalone","Yes",IF(AND(E9="Total",OR(B9="Kidnapping & Abduction (Total)",B9="Rape (Total)",B9="Attempt to Rape (Total)",B9="Assault to Outrage Modesty (Total)",B9="Insult to Modesty (Total)",B9="Immoral Traffic (Prevention) Act (Total)",B9="Women-Centric Cyber Crime (Total)",B9="POCSO (Protection of Children from Sexual Offences Act) (Total)")),"Yes","No")) -> Yes
A10: Andhra Pradesh | B10: Kidnapping & Abduction | C10: Kidnapping & Abduction | D10: 334 | E10: Detail | F10: =IF(E10="Standalone","Yes",IF(AND(E10="Total",OR(B10="Kidnapping & Abduction (Total)",B10="Rape (Total)",B10="Attempt to Rape (Total)",B10="Assault to Outrage Modesty (Total)",B10="Insult to Modesty (Total)",B10="Immoral Traffic (Prevention) Act (Total)",B10="Women-Centric Cyber Crime (Total)",B10="POCSO (Protection of Children from Sexual Offences Act) (Total)")),"Yes","No")) -> No
A11: Andhra Pradesh | B11: Kidnapping for Murder | C11: Kidnapping & Abduction | D11: 1 | E11: Detail | F11: =IF(E11="Standalone","Yes",IF(AND(E11="Total",OR(B11="Kidnapping & Abduction (Total)",B11="Rape (Total)",B11="Attempt to Rape (Total)",B11="Assault to Outrage Modesty (Total)",B11="Insult to Modesty (Total)",B11="Immoral Traffic (Prevention) Act (Total)",B11="Women-Centric Cyber Crime (Total)",B11="POCSO (Protection of Children from Sexual Offences Act) (Total)")),"Yes","No")) -> No
A12: Andhra Pradesh | B12: Kidnapping for Ransom | C12: Kidnapping & Abduction | D12: 5 | E12: Detail | F12: =IF(E12="Standalone","Yes",IF(AND(E12="Total",OR(B12="Kidnapping & Abduction (Total)",B12="Rape (Total)",B12="Attempt to Rape (Total)",B12="Assault to Outrage Modesty (Total)",B12="Insult to Modesty (Total)",B12="Immoral Traffic (Prevention) Act (Total)",B12="Women-Centric Cyber Crime (Total)",B12="POCSO (Protection of Children from Sexual Offences Act) (Total)")),"Yes","No")) -> No
A13: Andhra Pradesh | B13: Kidnapping for Marriage (Total) | C13: Kidnapping & Abduction | D13: 132 | E13: Total | F13: =IF(E13="Standalone","Yes",IF(AND(E13="Total",OR(B13="Kidnapping & Abduction (Total)",B13="Rape (Total)",B13="Attempt to Rape (Total)",B13="Assault to Outrage Modesty (Total)",B13="Insult to Modesty (Total)",B13="Immoral Traffic (Prevention) Act (Total)",B13="Women-Centric Cyber Crime (Total)",B13="POCSO (Protection of Children from Sexual Offences Act) (Total)")),"Yes","No")) -> No
... A1837: Puducherry | B1837: Indecent Representation of Women Act | C1837: Indecent Representation | D1837: 0 | E1837: Standalone | F1837: =IF(E1837="Standalone","Yes",IF(AND(E1837="Total",OR(B1837="Kidnapping & Abduction (Total)",B1837="Rape (Total)",B1837="Attempt to Rape (Total)",B1837="Assault to Outrage Modesty (Total)",B1837="Insult to Modesty (Total)",B1837="Immoral Traffic (Prevention) Act (Total)",B1837="Women-Centric Cyber Crime (Total)",B1837="POCSO (Protection of Children from Sexual Offences Act) (Total)")),"Yes","No")) -> Yes

Sheet Analysis
A1: State/UT Analysis | E1: Crime Category Analysis | I1: Crime Head Analysis | M1: Comparative Analysis
A3: Analysis Include | B3: Yes | E3: Analysis Include | F3: Yes | I3: Analysis Include | J3: Yes | M3: Analysis Include | N3: Yes
A5: State/UT | B5: Reported Cases | C5: Percentage of Total | E5: Crime Category | F5: Reported Cases | G5: Percentage of Total | I5: Row Labels | J5: Reported Cases | K5: Percentage of Total | M5: Reported Cases | N5: Crime Category
A6: Uttar Pradesh | B6: 66392 | C6: 0.19132204 | E6: Domestic Violence | F6: 134308 | G6: 0.29306654 | I6: Cruelty by Husband/Relatives | J6: 133676 | K6: 0.30000382 | M6: State/UT | N6: Abetment to Suicide | O6: Acid Attack | P6: Assault on Women | Q6: Attempt to Rape | R6: Cyber Crime | S6: Domestic Violence | T6: Dowry Death | U6: Dowry Prohibition Act | V6: Human Trafficking | W6: Immoral Traffic | X6: Indecent Representation | Y6: Insult to Modesty | Z6: Kidnapping & Abduction | AA6: Miscarriage | AB6: Murder with Rape | AC6: POCSO | AD6: Rape
A7: Maharashtra | B7: 47167 | C7: 0.13592129 | E7: Kidnapping & Abduction | F7: 98679 | G7: 0.21532234 | I7: Kidnapping & Abduction (Total) | J7: 88605 | K7: 0.19885273 | M7: Andaman and Nicobar Islands | N7: 2 | O7: 0 | P7: 31 | Q7: 0 | R7: 29 | S7: 6 | T7: 0 | U7: 0 | V7: 0 | W7: 0 | X7: 0 | Y7: 12 | Z7: 16 | AA7: 0 | AB7: 0 | AC7: 95 | AD7: 14
A8: Rajasthan | B8: 46887 | C8: 0.13511442 | E8: Assault on Women | F8: 83891 | G8: 0.18305421 | I8: Assault to Outrage Modesty (Total) | J8: 83891 | K8: 0.18827329 | M8: Andhra Pradesh | N8: 386 | O8: 7 | P8: 4930 | Q8: 112 | R8: 79 | S8: 10594 | T8: 95 | U8: 353 | V8: 81 | W8: 68 | X8: 3 | Y8: 2826 | Z8: 576 | AA8: 10 | AB8: 5 | AC8: 1907 | AD8: 438
A9: West Bengal | B9: 36762 | C9: 0.10593717 | E9: POCSO | F9: 66232 | G9: 0.14452142 | I9: POCSO (Protection of Children from Sexual Offences Act) (Total) | J9: 66232 | K9: 0.14864189 | M9: Arunachal Pradesh | N9: 3 | O9: 0 | P9: 74 | Q9: 5 | R9: 0 | S9: 58 | T9: 1 | U9: 0 | V9: 5 | W9: 0 | X9: 0 | Y9: 16 | Z9: 44 | AA9: 0 | AB9: 0 | AC9: 55 | AD9: 71
A10: Madhya Pradesh | B10: 32389 | C10: 0.093335485 | E10: Rape | F10: 29670 | G10: 0.064741373 | I10: Rape (Total) | J10: 29670 | K10: 0.06658722 | M10: Assam | N10: 102 | O10: 6 | P10: 1595 | Q10: 173 | R10: 182 | S10: 2926 | T10: 101 | U10: 162 | V10: 86 | W10: 30 | X10: 0 | Y10: 42 | Z10: 4186 | AA10: 4 | AB10: 13 | AC10: 2549 | AD10: 989
A11: Odisha | B11: 26052 | C11: 0.075074132 | E11: Dowry Prohibition Act | F11: 15489 | G11: 0.033797746 | I11: Dowry Prohibition Act | J11: 15489 | K11: 0.034761357 | M11: Bihar | N11: 3 | O11: 5 | P11: 472 | Q11: 47 | R11: 100 | S11: 2033 | T11: 1143 | U11: 3665 | V11: 28 | W11: 58 | X11: 2 | Y11: 47 | Z11: 13929 | AA11: 0 | AB11: 4 | AC11: 2307 | AD11: 902
A12: Bihar | B12: 24745 | C12: 0.071307746 | E12: Insult to Modesty | F12: 8823 | G12: 0.019252212 | I12: Insult to Modesty (Total) | J12: 8823 | K12: 0.019801114 | M12: Chandigarh | N12: 5 | O12: 0 | P12: 40 | Q12: 1 | R12: 5 | S12: 76 | T12: 4 | U12: 0 | V12: 2 | W12: 0 | X12: 0 | Y12: 5 | Z12: 134 | AA12: 0 | AB12: 0 | AC12: 0 | AD12: 102
A13: Telangana | B13: 23794 | C13: 0.068567246 | E13: Dowry Death | F13: 6156 | G13: 0.013432689 | I13: Other Kidnapping Cases | J13: 8214 | K13: 0.018434359 | M13: Chhattisgarh | N13: 122 | O13: 1 | P13: 1034 | Q13: 5 | R13: 198 | S13: 755 | T13: 46 | U13: 8 | V13: 14 | W13: 12 | X13: 0 | Y13: 241 | Z13: 2458 | AA13: 5 | AB13: 5 | AC13: 1978 | AD13: 1171
A14: Andhra Pradesh | B14: 22470 | C14: 0.064751871 | E14: Abetment to Suicide | F14: 4825 | G14: 0.010528383 | I14: Dowry Deaths | J14: 6156 | K14: 0.01381567 | M14: Dadra and Nagar Haveli and Daman and Diu | N14: 1 | O14: 0 | P14: 12 | Q14: 1 | R14: 3 | S14: 2 | T14: 0 | U14: 0 | V14: 0 | W14: 8 | X14: 0 | Y14: 3 | Z14: 36 | AA14: 0 | AB14: 0 | AC14: 53 | AD14: 6
A15: Karnataka | B15: 20359 | C15: 0.058668595 | E15: Cyber Crime | F15: 3678 | G15: 0.0080255736 | I15: Abetment to Suicide of Women | J15: 4825 | K15: 0.010828559 | M15: Delhi | N15: 42 | O15: 8 | P15: 1814 | Q15: 0 | R15: 36 | S15: 4240 | T15: 115 | U15: 16 | V15: 44 | W15: 59 | X15: 0 | Y15: 352 | Z15: 4099 | AA15: 10 | AB15: 3 | AC15: 1636 | AD15: 1094
E16: Attempt to Rape | F16: 2796 | G16: 0.006101007 | M16: Goa | N16: 3 | O16: 0 | P16: 96 | Q16: 0 | R16: 9 | S16: 0 | T16: 1 | U16: 0 | V16: 8 | W16: 0 | X16: 0 | Y16: 21 | Z16: 61 | AA16: 0 | AB16: 0 | AC16: 0 | AD16: 97
E17: Immoral Traffic | F17: 1788 | G17: 0.0039015023 | M17: Gujarat | N17: 318 | O17: 3 | P17: 688 | Q17: 0 | R17: 54 | S17: 2178 | T17: 12 | U17: 3 | V17: 3 | W17: 80 | X17: 0 | Y17: 15 | Z17: 1300 | AA17: 5 | AB17: 7 | AC17: 2548 | AD17: 634
E18: Human Trafficking | F18: 1226 | G18: 0.0026751912 | M18: Haryana | N18: 178 | O18: 4 | P18: 2265 | Q18: 199 | R18: 103 | S18: 5196 | T18: 207 | U18: 14 | V18: 32 | W18: 38 | X18: 0 | Y18: 443 | Z18: 5071 | AA18: 50 | AB18: 9 | AC18: 2044 | AD18: 1772
E19: Miscarriage | F19: 309 | G19: 0.00067425292 | M19: Himachal Pradesh | N19: 39 | O19: 0 | P19: 504 | Q19: 3 | R19: 21 | S19: 219 | T19: 0 | U19: 2 | V19: 5 | W19: 10 | X19: 0 | Y19: 97 | Z19: 358 | AA19: 0 | AB19: 6 | AC19: 3 | AD19: 344
E20: Murder with Rape | F20: 230 | G20: 0.00050187111 | M20: Jammu and Kashmir | N20: 31 | O20: 0 | P20: 1542 | Q20: 2 | R20: 43 | S20: 524 | T20: 9 | U20: 15 | V20: 7 | W20: 8 | X20: 0 | Y20: 21 | Z20: 1011 | AA20: 4 | AB20: 1 | AC20: 320 | AD20: 231
E21: Acid Attack | F21: 154 | G21: 0.00033603544 | M21: Jharkhand | N21: 45 | O21: 1 | P21: 944 | Q21: 66 | R21: 12 | S21: 866 | T21: 218 | U21: 1487 | V21: 37 | W21: 2 | X21: 0 | Y21: 4 | Z21: 1629 | AA21: 3 | AB21: 3 | AC21: 827 | AD21: 1221
E22: Indecent Representation | F22: 31 | G22: 6.7643497e-05 | M22: Karnataka | N22: 274 | O22: 4 | P22: 6790 | Q22: 10 | R22: 458 | S22: 3000 | T22: 156 | U22: 2322 | V22: 11 | W22: 308 | X22: 1 | Y22: 148 | Z22: 2350 | AA22: 11 | AB22: 6 | AC22: 3854 | AD22: 656
M23: Kerala | N23: 47 | O23: 9 | P23: 4816 | Q23: 54 | R23: 369 | S23: 5190 | T23: 8 | U23: 21 | V23: 15 | W23: 13 | X23: 0 | Y23: 679 | Z23: 238 | AA23: 1 | AB23: 4 | AC23: 3765 | AD23: 843
M24: Ladakh | N24: 0 | O24: 0 | P24: 2 | Q24: 0 | R24: 0 | S24: 6 | T24: 0 | U24: 0 | V24: 0 | W24: 0 | X24: 0 | Y24: 4 | Z24: 3 | AA24: 0 | AB24: 0 | AC24: 3 | AD24: 2
M25: Lakshadweep | N25: 0 | O25: 0 | P25: 7 | Q25: 0 | R25: 1 | S25: 3 | T25: 0 | U25: 0 | V25: 0 | W25: 0 | X25: 1 | Y25: 1 | Z25: 0 | AA25: 0 | AB25: 0 | AC25: 9 | AD25: 1
M26: Madhya Pradesh | N26: 716 | O26: 5 | P26: 5078 | Q26: 38 | R26: 52 | S26: 7597 | T26: 468 | U26: 65 | V26: 37 | W26: 21 | X26: 4 | Y26: 243 | Z26: 8604 | AA26: 24 | AB26: 29 | AC26: 6429 | AD26: 2979
M27: Maharashtra | N27: 742 | O27: 8 | P27: 12133 | Q27: 0 | R27: 81 | S27: 11234 | T27: 170 | U27: 17 | V27: 315 | W27: 211 | X27: 0 | Y27: 1309 | Z27: 9427 | AA27: 42 | AB27: 29 | AC27: 8519 | AD27: 2930
M28: Manipur | N28: 4 | O28: 0 | P28: 66 | Q28: 0 | R28: 0 | S28: 7 | T28: 1 | U28: 0 | V28: 0 | W28: 0 | X28: 0 | Y28: 8 | Z28: 49 | AA28: 0 | AB28: 1 | AC28: 55 | AD28: 27
M29: Meghalaya | N29: 2 | O29: 1 | P29: 51 | Q29: 12 | R29: 10 | S29: 14 | T29: 0 | U29: 2 | V29: 0 | W29: 1 | X29: 0 | Y29: 17 | Z29: 61 | AA29: 1 | AB29: 0 | AC29: 397 | AD29: 66
M30: Mizoram | N30: 0 | O30: 0 | P30: 28 | Q30: 1 | R30: 0 | S30: 5 | T30: 0 | U30: 0 | V30: 0 | W30: 0 | X30: 0 | Y30: 0 | Z30: 1 | AA30: 0 | AB30: 0 | AC30: 113 | AD30: 36
M31: Nagaland | N31: 0 | O31: 0 | P31: 14 | Q31: 3 | R31: 1 | S31: 4 | T31: 0 | U31: 0 | V31: 0 | W31: 1 | X31: 0 | Y31: 1 | Z31: 9 | AA31: 0 | AB31: 0 | AC31: 15 | AD31: 10
M32: Odisha | N32: 0 | O32: 7 | P32: 9367 | Q32: 123 | R32: 761 | S32: 5534 | T32: 231 | U32: 5 | V32: 105 | W32: 15 | X32: 8 | Y32: 569 | Z32: 5749 | AA32: 0 | AB32: 15 | AC32: 2368 | AD32: 1195
M33: Puducherry | N33: 4 | O33: 0 | P33: 30 | Q33: 1 | R33: 10 | S33: 9 | T33: 1 | U33: 14 | V33: 15 | W33: 3 | X33: 0 | Y33: 9 | Z33: 17 | AA33: 0 | AB33: 0 | AC33: 91 | AD33: 9
M34: Punjab | N34: 198 | O34: 3 | P34: 656 | Q34: 23 | R34: 37 | S34: 1532 | T34: 44 | U34: 4 | V34: 20 | W34: 39 | X34: 0 | Y34: 20 | Z34: 1464 | AA34: 7 | AB34: 6 | AC34: 782 | AD34: 457
... M42: West Bengal | N42: 419 | O42: 37 | P42: 2479 | Q42: 825 | R42: 9 | S42: 19698 | T42: 350 | U42: 0 | V42: 31 | W42: 32 | X42: 1 | Y42: 412 | Z42: 8615 | AA42: 16 | AB42: 7 | AC42: 2721 | AD42: 1110
A45: KPI Support
A47: KPI | B47: Result | C47: Cases
A48: Total Reported Cases | B48: Total | C48: 4,58,285
A49: States/UTs Analyzed | B49: Total | C49: 36
A50: Crime Categories | B50: Total | C50: 17
A51: Crime Heads Analyzed | B51: Total | C51: 51
A52: Highest Crime State/UT | B52: Uttar Pradesh | C52: 66392
...

Sheet Dashboard
A1: CRIME AGAINST WOMEN - 2023 DATA ANALYSIS
A2: State, Crime Category and Crime Head Analysis
A3: Source: NCRB / data.gov.in
A5: Total Reported Cases | F5: States/UTs Analyzed | K5: Crime Categories | P5: Crime Heads Analyzed
A7: =Analysis!C48 -> 4,58,285 | F7: =Analysis!C49 -> 36 | K7: =Analysis!C50 -> 17 | P7: =Analysis!C51 -> 51
A11: Highest-reporting State/UT | F11: Highest Crime Category | K11: Highest Crime Head
A13: =Analysis!B52 -> Uttar Pradesh | F13: =Analysis!B53 -> Domestic Violence | K13: =Analysis!B54 -> Cruelty by Husband/Relatives
A15: =Analysis!C52 -> 66392 | F15: =Analysis!C53 -> 1,34,308 | K15: =Analysis!C54 -> 1,33,676
A30: Top 10 States/UTs | G30: Cases by Crime Category | N30: Top 10 Crime Heads | P30: Top 10 Crime Heads

Sheet Key_Insights
A1: KEY INSIGHTS & INTERPRETATION
A3: Crime Against Women — 2023
A4: Source: NCRB / data.gov.in
A6: EXECUTIVE SUMMARY
A8: The analysis examines reported crime cases against women across 36 States/Uts and 17 Crime Categories.
A9: SQL and Excel were used to validate, aggregate, rank and visualize the data to identify geographic and crime-pattern trends.
A11: Key Findings
A13: # | B13: Finding | C13: Evidence | D13: Interpretation
A14: 1 | B14: Highest-reporting State/UT | C14: Uttar Pradesh - 66,392 Cases | D14: Identifies the State/UT with the highest reported cases
A15: 2 | B15: Top 5 States/UTs contribution | C15: 50.10% (UP, Maharashtra, Rajasthan, West Bengal, MP) | D15: Shows how concentrated reported cases are geographically
A16: 3 | B16: Highest-Reporting Crime Category | C16: Domestic Violence - 1,34,308 Cases | D16: Identifies the category with the largest reported case count
A17: 4 | B17: Highest-Reporting Crime Head | C17: Cruelty by Husband / Relatives - 1,33,676 Cases | D17: Identifies the most reported individual Crime Head
A18: 5 | B18: Top 10 Crime Heads contribution | C18: 0.9723 | D18: Shows concentration among the most reported Crime Heads
A19: 6 | B19: States/UTs above average | C19: 14 States / Uts (Uttar Pradesh, Maharashtra, Rajasthan, etc.) | D19: Shows how reported cases are distributed relative to the average
A21: Data Interpretation Note
A23: The dataset contains aggregate Crime Head records marked as "(Total)" alongside corresponding component Crime Heads.
A24: These records represent hierarchical/related measures and should not automatically be summed together as independent crimes.
A25: Crime Head-level comparisons therefore consider the structure of the source data when interpreting results.
A27: Methodology
A29: Stage | B29: Methods Used
A30: Data Source | B30: NCRB dataset obtained through data.gov.in
A31: Data Preparation | B31: Data cleaning, normalization and Crime Category classification
A32: Data Validation | B32: NULL, duplicate and invalid-value checks
A33: SQL Analysis | B33: Aggregation, filtering, subqueries, CTEs and window functions
A34: Excel Analysis | B34: PivotTables and calculated percentages
A35: Visualization | B35: PivotCharts, slicers and KPI cards
A36: Interpretation | B36: Geographic, category and Crime Head comparisons
